Workbook

Sheet 2000Year
A1: Source | B1: Destination | C1: Pair | D1: Delay_Min | E1: Delay_Max | F1: Delay_Mean | G1: Delay_Median | H1: Direct_Loss_Min_Pct | I1: Direct_Loss_Max_Pct | J1: Direct_Loss_Mean_Pct | K1: Direct_Loss_Median_Pct | L1: Backbone_Loss_Min_Pct | M1: Backbone_Loss_Max_Pct | N1: Backbone_Loss_Mean_Pct | O1: Backbone_Loss_Median_Pct | P1: Total_Attempts | Q1: Failed_Attempts | R1: Blackout_Loss_Pct | S1: MultiHop_Reroutes | T1: Reroute_Pct
A2: Ceres | B2: Earth | C2: Ceres-Earth | D2: 14.71 | E2: 36.62 | F2: 23.82 | G2: 24.48 | H2: 0.1318 | I2: 0.2821 | J2: 0.203 | K2: 0.2093 | L2: 0.0749 | M2: 0.0842 | N2: 0.0764 | O2: 0.0762 | P2: 730000 | Q2: 0 | R2: 0 | S2: 31667 | T2: 0.0434
A3: Ceres | B3: Jupiter | C3: Ceres-Jupiter | D3: 20.28 | E3: 68.41 | F3: 46.44 | G3: 49.07 | H3: 0.1771 | I3: 0.482 | J3: 0.3521 | K3: 0.3754 | L3: 0.1473 | M3: 0.3624 | N3: 0.148 | O3: 0.1476 | P3: 730000 | Q3: 0 | R3: 0 | S3: 12882 | T3: 0.0176
A4: Ceres | B4: Mars | C4: Ceres-Mars | D4: 10.36 | E4: 38.51 | F4: 24.82 | G4: 26.27 | H4: 0.0947 | I4: 0.3088 | J4: 0.2089 | K4: 0.2224 | L4: 0.0821 | M4: 0.2065 | N4: 0.0839 | O4: 0.0829 | P4: 730000 | Q4: 0 | R4: 0 | S4: 23645 | T4: 0.0324
A5: Ceres | B5: Mercury | C5: Ceres-Mercury | D5: 19.81 | E5: 36.93 | F5: 23.41 | G5: 23.25 | H5: 0.1734 | I5: 0.2952 | J5: 0.1998 | K5: 0.199 | L5: 0.0609 | M5: 0.1689 | N5: 0.0668 | O5: 0.0658 | P5: 730000 | Q5: 0 | R5: 0 | S5: 69115 | T5: 0.0947
A6: Ceres | B6: Neptune | C6: Ceres-Neptune | D6: 227.08 | E6: 274.4 | F6: 250.63 | G6: 251.15 | H6: 0.8874 | I6: 0.9286 | J6: 0.9091 | K6: 0.9106 | L6: 0.4814 | M6: 0.9109 | N6: =48.24% * 1.3 -> 0.62712 | O6: 0.4815 | P6: 730000 | Q6: 0 | R6: 0 | S6: 9172 | T6: 0.0126
A7: Ceres | B7: Saturn | C7: Ceres-Saturn | D7: 56.32 | E7: 103.61 | F7: 81.03 | G7: 82.64 | H7: 0.4182 | I7: 0.6308 | J7: 0.5354 | K7: 0.5478 | L7: 0.2181 | M7: 0.5492 | N7: 0.22 | O7: 0.2183 | P7: 730000 | Q7: 0 | R7: 0 | S7: 10856 | T7: 0.0149
A8: Ceres | B8: Uranus | C8: Ceres-Uranus | D8: 136.61 | E8: 183.88 | F8: 160.44 | G8: 161.24 | H8: 0.7312 | I8: 0.8294 | J8: 0.7835 | K8: 0.7877 | L8: 0.3554 | M8: 0.7916 | N8: =35.74% * 1.3 -> 0.46462 | O8: 0.3556 | P8: 730000 | Q8: 0 | R8: 0 | S8: 9596 | T8: 0.0131
A9: Ceres | B9: Venus | C9: Ceres-Venus | D9: 17.01 | E9: 35.93 | F9: 23.48 | G9: 23.8 | H9: 0.1508 | I9: 0.292 | J9: 0.2007 | K9: 0.2037 | L9: 0.0673 | M9: 0.2034 | N9: 0.0717 | O9: 0.0695 | P9: 730000 | Q9: 0 | R9: 0 | S9: 40622 | T9: 0.0556
A10: Earth | B10: Ceres | C10: Earth-Ceres | D10: 14.71 | E10: 36.62 | F10: 23.82 | G10: 24.48 | H10: 0.1318 | I10: 0.2821 | J10: 0.203 | K10: 0.2093 | L10: 0.0749 | M10: 0.0842 | N10: 0.0764 | O10: 0.0762 | P10: 730000 | Q10: 0 | R10: 0 | S10: 31667 | T10: 0.0434
A11: Earth | B11: Jupiter | C11: Earth-Jupiter | D11: 34.97 | E11: 56.24 | F11: 43.71 | G11: 44.08 | H11: 0.2856 | I11: 0.4084 | J11: 0.3419 | K11: 0.3451 | L11: 0.1183 | M11: 0.1264 | N11: 0.1194 | O11: 0.1192 | P11: 730000 | Q11: 0 | R11: 0 | S11: 27739 | T11: 0.038
A12: Earth | B12: Mars | C12: Earth-Mars | D12: 4.37 | E12: 26.61 | F12: 14.15 | G12: 15.17 | H12: 0.041 | I12: 0.2149 | J12: 0.1255 | K12: 0.1353 | L12: 0.0533 | M12: 0.0795 | N12: 0.0554 | O12: 0.0551 | P12: 730000 | Q12: 0 | R12: 0 | S12: 38537 | T12: 0.0528
A13: Earth | B13: Mercury | C13: Earth-Mercury | D13: 5.11 | E13: 22.92 | F13: 9.22 | G13: 8.93 | H13: 0.0478 | I13: 0.1839 | J13: 0.0804 | K13: 0.08 | L13: 0.0393 | M13: 0.0709 | N13: 0.0409 | O13: 0.0409 | P13: 730000 | Q13: 0 | R13: 0 | S13: 83990 | T13: 0.1151
A14: Earth | B14: Neptune | C14: Earth-Neptune | D14: 241.78 | E14: 262.25 | F14: 250.18 | G14: 250.23 | H14: 0.9023 | I14: 0.919 | J14: 0.9097 | K14: 0.9099 | L14: 0.4635 | M14: 0.4855 | N14: =46.41% * 1.3 -> 0.60333 | O14: 0.4639 | P14: 730000 | Q14: 0 | R14: 0 | S14: 24056 | T14: 0.033
A15: Earth | B15: Saturn | C15: Earth-Saturn | D15: 71.02 | E15: 91.98 | F15: 79.57 | G15: 79.77 | H15: 0.4949 | I15: 0.5796 | J15: 0.5339 | K15: 0.5354 | L15: 0.1913 | M15: 0.1984 | N15: 0.1921 | O15: 0.192 | P15: 730000 | Q15: 0 | R15: 0 | S15: 25717 | T15: 0.0352
A16: Earth | B16: Uranus | C16: Earth-Uranus | D16: 151.31 | E16: 172.2 | F16: 159.75 | G16: 159.84 | H16: 0.7667 | I16: 0.8059 | J16: 0.7844 | K16: 0.7849 | L16: 0.3332 | M16: 0.3591 | N16: =33.39% * 1.3 -> 0.43407 | O16: 0.3337 | P16: 730000 | Q16: 0 | R16: 0 | S16: 24476 | T16: 0.0335
A17: Earth | B17: Venus | C17: Earth-Venus | D17: 2.32 | E17: 22.51 | F17: 9.62 | G17: 10.28 | H17: 0.0219 | I17: 0.1462 | J17: 0.0859 | K17: 0.0928 | L17: 0.0449 | M17: 0.0526 | N17: 0.0466 | O17: 0.0466 | P17: 730000 | Q17: 0 | R17: 0 | S17: 55493 | T17: 0.076
A18: Jupiter | B18: Ceres | C18: Jupiter-Ceres | D18: 20.28 | E18: 68.41 | F18: 46.44 | G18: 49.07 | H18: 0.1771 | I18: 0.482 | J18: 0.3521 | K18: 0.3754 | L18: 0.1473 | M18: 0.3624 | N18: 0.148 | O18: 0.1476 | P18: 730000 | Q18: 0 | R18: 0 | S18: 12882 | T18: 0.0176
A19: Jupiter | B19: Earth | C19: Jupiter-Earth | D19: 34.97 | E19: 56.24 | F19: 43.71 | G19: 44.08 | H19: 0.2856 | I19: 0.4084 | J19: 0.3419 | K19: 0.3451 | L19: 0.1183 | M19: 0.1264 | N19: 0.1194 | O19: 0.1192 | P19: 730000 | Q19: 0 | R19: 0 | S19: 27739 | T19: 0.038
A20: Jupiter | B20: Mars | C20: Jupiter-Mars | D20: 30.62 | E20: 59.14 | F20: 44.23 | G20: 45.11 | H20: 0.255 | I20: 0.4294 | J20: 0.3436 | K20: 0.3513 | L20: 0.1258 | M20: 0.3469 | N20: 0.1279 | O20: 0.1264 | P20: 730000 | Q20: 0 | R20: 0 | S20: 19723 | T20: 0.027
A21: Jupiter | B21: Mercury | C21: Jupiter-Mercury | D21: 40.07 | E21: 57.15 | F21: 43.57 | G21: 43.41 | H21: 0.3198 | I21: 0.4227 | J21: 0.341 | K21: 0.3402 | L21: 0.1055 | M21: 0.1405 | N21: 0.1105 | O21: 0.1094 | P21: 730000 | Q21: 0 | R21: 0 | S21: 65184 | T21: 0.0893
A22: Jupiter | B22: Neptune | C22: Jupiter-Neptune | D22: 206.82 | E22: 293.97 | F22: 252.05 | G22: 253.94 | H22: 0.8632 | I22: 0.9408 | J22: 0.9075 | K22: 0.913 | L22: 0.5061 | M22: 0.9151 | N22: =50.65% * 1.3 -> 0.65845 | O22: 0.5062 | P22: 730000 | Q22: 0 | R22: 0 | S22: 5181 | T22: 0.0071
A23: Jupiter | B23: Saturn | C23: Jupiter-Saturn | D23: 36.06 | E23: 123.49 | F23: 85.48 | G23: 90.57 | H23: 0.293 | I23: 0.695 | J23: 0.5416 | K23: 0.581 | L23: 0.2553 | M23: 0.5704 | N23: 0.2561 | O23: 0.2554 | P23: 730000 | Q23: 0 | R23: 0 | S23: 6927 | T23: 0.0095
A24: Jupiter | B24: Uranus | C24: Jupiter-Uranus | D24: 116.35 | E24: 203.58 | F24: 162.5 | G24: 165.25 | H24: 0.6734 | I24: 0.8588 | J24: 0.7812 | K24: 0.7957 | L24: 0.3861 | M24: 0.656 | N24: =38.64% * 1.3 -> 0.50232 | O24: 0.3862 | P24: 730000 | Q24: 0 | R24: 0 | S24: 5648 | T24: 0.0077
A25: Jupiter | B25: Venus | C25: Jupiter-Venus | D25: 37.28 | E25: 56.37 | F25: 43.55 | G25: 43.71 | H25: 0.3012 | I25: 0.4144 | J25: 0.3411 | K25: 0.3425 | L25: 0.1116 | M25: 0.3451 | N25: 0.1156 | O25: 0.1132 | P25: 730000 | Q25: 0 | R25: 0 | S25: 36694 | T25: 0.0503
A26: Mars | B26: Ceres | C26: Mars-Ceres | D26: 10.36 | E26: 38.51 | F26: 24.82 | G26: 26.27 | H26: 0.0947 | I26: 0.3088 | J26: 0.2089 | K26: 0.2224 | L26: 0.0821 | M26: 0.2065 | N26: 0.0839 | O26: 0.0829 | P26: 730000 | Q26: 0 | R26: 0 | S26: 23645 | T26: 0.0324
A27: Mars | B27: Earth | C27: Mars-Earth | D27: 4.37 | E27: 26.61 | F27: 14.15 | G27: 15.17 | H27: 0.041 | I27: 0.2149 | J27: 0.1255 | K27: 0.1353 | L27: 0.0533 | M27: 0.0619 | N27: 0.0554 | O27: 0.0551 | P27: 730000 | Q27: 0 | R27: 0 | S27: 38537 | T27: 0.0528
A28: Mars | B28: Jupiter | C28: Mars-Jupiter | D28: 30.62 | E28: 59.14 | F28: 44.23 | G28: 45.11 | H28: 0.255 | I28: 0.4294 | J28: 0.3436 | K28: 0.3513 | L28: 0.1258 | M28: 0.3469 | N28: 0.1278 | O28: 0.1264 | P28: 730000 | Q28: 0 | R28: 0 | S28: 19723 | T28: 0.027
A29: Mars | B29: Mercury | C29: Mars-Mercury | D29: 9.47 | E29: 26.92 | F29: 13.28 | G29: 13.09 | H29: 0.0869 | I29: 0.2261 | J29: 0.1175 | K29: 0.1167 | L29: 0.0372 | M29: 0.084 | N29: 0.0457 | O29: 0.0447 | P29: 730000 | Q29: 0 | R29: 0 | S29: 75980 | T29: 0.1041
A30: Mars | B30: Neptune | C30: Mars-Neptune | D30: 237.42 | E30: 265.14 | F30: 250.26 | G30: 250.42 | H30: 0.8981 | I30: 0.9218 | J30: 0.9095 | K30: 0.91 | L30: 0.4684 | M30: 0.9106 | N30: =47.2% * 1.3 -> 0.6136 | O30: 0.4686 | P30: 730000 | Q30: 0 | R30: 0 | S30: 16044 | T30: 0.022
A31: Mars | B31: Saturn | C31: Mars-Saturn | D31: 66.66 | E31: 94.87 | F31: 79.85 | G31: 80.34 | H31: 0.4733 | I31: 0.5984 | J31: 0.534 | K31: 0.5378 | L31: 0.1984 | M31: 0.5381 | N31: 0.2008 | O31: 0.1988 | P31: 730000 | Q31: 0 | R31: 0 | S31: 17702 | T31: 0.0242
A32: Mars | B32: Uranus | C32: Mars-Uranus | D32: 146.95 | E32: 175.15 | F32: 159.88 | G32: 160.12 | H32: 0.7567 | I32: 0.8145 | J32: 0.7842 | K32: 0.7855 | L32: 0.3392 | M32: 0.7866 | N32: =34.04% * 1.3 -> 0.44252 | O32: 0.3395 | P32: 730000 | Q32: 0 | R32: 0 | S32: 16456 | T32: 0.0225
A33: Mars | B33: Venus | C33: Mars-Venus | D33: 6.67 | E33: 26.42 | F33: 13.51 | G33: 14.04 | H33: 0.062 | I33: 0.2241 | J33: 0.1201 | K33: 0.1253 | L33: 0.0438 | M33: 0.1229 | N33: 0.051 | O33: 0.0497 | P33: 730000 | Q33: 0 | R33: 0 | S33: 47483 | T33: 0.065
A34: Mercury | B34: Ceres | C34: Mercury-Ceres | D34: 19.81 | E34: 36.93 | F34: 23.41 | G34: 23.25 | H34: 0.1734 | I34: 0.2952 | J34: 0.1998 | K34: 0.199 | L34: 0.0609 | M34: 0.0983 | N34: 0.0668 | O34: 0.0658 | P34: 730000 | Q34: 0 | R34: 0 | S34: 69115 | T34: 0.0947
A35: Mercury | B35: Earth | C35: Mercury-Earth | D35: 5.11 | E35: 22.92 | F35: 9.22 | G35: 8.93 | H35: 0.0478 | I35: 0.1839 | J35: 0.0804 | K35: 0.08 | L35: 0.0393 | M35: 0.0536 | N35: 0.0409 | O35: 0.0409 | P35: 730000 | Q35: 0 | R35: 0 | S35: 83990 | T35: 0.1151
A36: Mercury | B36: Jupiter | C36: Mercury-Jupiter | D36: 40.07 | E36: 57.15 | F36: 43.57 | G36: 43.41 | H36: 0.3198 | I36: 0.4227 | J36: 0.341 | K36: 0.3402 | L36: 0.1055 | M36: 0.1405 | N36: 0.1105 | O36: 0.1094 | P36: 730000 | Q36: 0 | R36: 0 | S36: 65184 | T36: 0.0893
A37: Mercury | B37: Mars | C37: Mercury-Mars | D37: 9.47 | E37: 26.92 | F37: 13.28 | G37: 13.09 | H37: 0.0869 | I37: 0.2261 | J37: 0.1175 | K37: 0.1167 | L37: 0.0372 | M37: 0.0791 | N37: 0.0457 | O37: 0.0447 | P37: 730000 | Q37: 0 | R37: 0 | S37: 75980 | T37: 0.1041
A38: Mercury | B38: Neptune | C38: Mercury-Neptune | D38: 246.87 | E38: 263.52 | F38: 250.27 | G38: 250.11 | H38: 0.9069 | I38: 0.9205 | J38: 0.9098 | K38: 0.9097 | L38: 0.456 | M38: 0.4787 | N38: =45.86% * 1.3 -> 0.59618 | O38: 0.4579 | P38: 730000 | Q38: 0 | R38: 0 | S38: 61486 | T38: 0.0842
A39: Mercury | B39: Saturn | C39: Mercury-Saturn | D39: 76.11 | E39: 92.53 | F39: 79.56 | G39: 79.4 | H39: 0.5191 | I39: 0.5892 | J39: 0.5339 | K39: 0.5333 | L39: 0.1798 | M39: 0.2107 | N39: 0.184 | O39: 0.183 | P39: 730000 | Q39: 0 | R39: 0 | S39: 63148 | T39: 0.0865
A40: Mercury | B40: Uranus | C40: Mercury-Uranus | D40: 156.41 | E40: 173.37 | F40: 159.81 | G40: 159.66 | H40: 0.7778 | I40: 0.8111 | J40: 0.7846 | K40: 0.7844 | L40: 0.3238 | M40: 0.3511 | N40: =32.71% * 1.3 -> 0.42523 | O40: 0.3262 | P40: 730000 | Q40: 0 | R40: 0 | S40: 61913 | T40: 0.0848
...

Sheet Sheet1
A1: Column1 | B1: Column2 | C1: Column3
A2: Mercury | B2: =SUM('2000Year'!N34:N41)/8 -> 0.18870125 | C2: =SUM('2000Year'!M34:M41)/8 -> 0.1889125
A3: Venus | B3: =SUM('2000Year'!N66:N73)/8 -> 0.1928425 | C3: =SUM('2000Year'!M66:M73)/8 -> 0.3292625
A4: Earth | B4: =SUM('2000Year'!N10:N17)/8 -> 0.196025 | C4: =SUM('2000Year'!M10:M17)/8 -> 0.182075
A5: Mars | B5: =SUM('2000Year'!N26:N33)/8 -> 0.20259 | C5: =SUM('2000Year'!M26:M33)/8 -> 0.3821875
A6: Ceres | B6: =SUM('2000Year'!N2:N9)/8 -> 0.2198175 | C6: =SUM('2000Year'!M2:M9)/8 -> 0.4096375
A7: Jupiter | B7: =SUM('2000Year'!N18:N25)/8 -> 0.25478375 | C7: =SUM('2000Year'!M18:M25)/8 -> 0.43285
A8: Saturn | B8: =SUM('2000Year'!N50:N57)/8 -> 0.3152775 | C8: =SUM('2000Year'!M50:M57)/8 -> 0.53375
A9: Uranus | B9: =SUM('2000Year'!N58:N65)/8 -> 0.41610125 | C9: =SUM('2000Year'!M58:M65)/8 -> 0.69605
A10: Neptune | B10: =SUM('2000Year'!N42:N49)/8 -> 0.52586375 | C10: =SUM('2000Year'!M42:M49)/8 -> 0.7712875
